Workbook

Sheet 📋 Инструкция
B2: ФИНАНСОВАЯ МОДЕЛЬ — ШАБЛОН ДЛЯ СТАРТАПА
B3: Горизонт: 12 месяцев | Валюта: рубли | Детализация: помесячно
B5: ЦВЕТОВАЯ КОДИРОВКА
B6: Синий текст | C6: Вводные данные (допущения) — вы меняете эти ячейки
B7: Чёрный текст | C7: Формулы и расчёты — не трогайте вручную
B8: Зелёный текст | C8: Ссылки на другие листы внутри файла
B9: Жёлтый фон | C9: Ключевые допущения, требующие вашего внимания
B11: ЛИСТЫ МОДЕЛИ
B12: 📋 Инструкция | C12: Этот лист — навигация и цветовые обозначения
B13: ⚙️ Допущения | C13: ВСЕ вводные данные модели. Только здесь вносите изменения!
B14: 📈 Выручка | C14: Расчёт выручки по продуктам/каналам от допущений
B15: 💸 Расходы | C15: Постоянные и переменные расходы с разбивкой
B16: 📊 ОПУ | C16: Отчёт о прибылях и убытках — план по месяцам
B17: 💰 ДДС | C17: Движение денежных средств — реальный кэш на счёте
B18: 🎯 Дашборд | C18: Ключевые метрики: runway, breakeven, юнит-экономика
B20: КАК РАБОТАТЬ С МОДЕЛЬЮ
B21: Шаг 1 | C21: Откройте лист ⚙️ Допущения и заполните синие ячейки под свой бизнес
B22: Шаг 2 | C22: Все остальные листы пересчитаются автоматически
B23: Шаг 3 | C23: Проверьте 🎯 Дашборд — там ключевые метрики и выводы
B24: Шаг 4 | C24: Каждый месяц вносите факт рядом с планом — так работает план-факт анализ
B25: Шаг 5 | C25: Скопируйте лист ⚙️ Допущения 3 раза для сценариев: Base / Best / Worst

Sheet ⚙️ Допущения
B2: ⚙️ ДОПУЩЕНИЯ — вводите данные ТОЛЬКО здесь
C3: Синий = вводные данные (вы меняете) | D3: Жёлтый фон = ключевые допущения
B5: 1. ОБЩИЕ СВЕДЕНИЯ
B6: Название компании | C6: Моя компания
B7: Год основания | C7: 2025 | D7: год
B8: Первый месяц модели (1=Янв) | C8: 1 | D8: мес | E8: 1 = январь, 7 = июль
B9: Год модели | C9: 2025 | D9: год
B11: 2. ВЫРУЧКА
B12: Продукт / услуга 1
B13: Средний чек | C13: 5000 | D13: ₽ | E13: Цена одной продажи / подписки
B14: Продаж в Январе | C14: 300 | D14: шт | E14: Стартовый объём продаж
B15: Ежемесячный рост продаж | C15: 0.05 | D15: % | E15: Рост числа продаж месяц к месяцу
B16: Отсрочка оплаты клиентом | C16: 1 | D16: мес | E16: 0 = сразу, 1 = следующий месяц
B18: Продукт / услуга 2 (если есть)
B19: Средний чек | C19: 0 | D19: ₽ | E19: 0 = не используется
B20: Продаж в Январе | C20: 0 | D20: шт
B21: Ежемесячный рост продаж | C21: 0.03 | D21: %
B22: Отсрочка оплаты клиентом | C22: 0 | D22: мес
B24: 3. ПОСТОЯННЫЕ РАСХОДЫ (ежемесячно)
B25: Аренда | C25: 50000 | D25: ₽
B26: ФОТ (фонд оплаты труда) | C26: 200000 | D26: ₽ | E26: Включая НДФЛ и взносы (~43% сверху)
B27: Маркетинг (фикс. часть) | C27: 30000 | D27: ₽
B28: Программное обеспечение / подписки | C28: 10000 | D28: ₽
B29: Прочие постоянные расходы | C29: 20000 | D29: ₽
B30: Рост постоянных расходов | C30: 0.02 | D30: % | E30: Ежемесячный рост постоянных расходов
B32: 4. ПЕРЕМЕННЫЕ РАСХОДЫ (% от выручки)
B33: Себестоимость (COGS) | C33: 0.3 | D33: % | E33: Доля от выручки: сырьё, материалы
B34: Эквайринг / комиссии | C34: 0.02 | D34: % | E34: Комиссия платёжных систем
B35: Переменный маркетинг | C35: 0.05 | D35: % | E35: Реклама, привлечение клиентов
B36: Прочие переменные | C36: 0.03 | D36: %
B38: 5. НАЛОГИ
B39: Налоговый режим | C39: УСН 6% | E39: УСН 6% / УСН 15% / ОСН
B40: Ставка налога (УСН доходы) | C40: 0.06 | D40: % | E40: 6% для УСН «доходы»
B41: Ставка налога (УСН д-р) | C41: 0.15 | D41: % | E41: 15% для УСН «доходы минус расходы»
B42: Авансы по налогу (ежекварт.) | C42: Да | E42: Налог платится авансами раз в квартал
B44: 6. СТАРТОВЫЕ ИНВЕСТИЦИИ
B45: Начальный остаток на счёте | C45: 500000 | D45: ₽ | E45: Деньги на момент старта модели
B46: Инвестиции в оборудование | C46: 100000 | D46: ₽ | E46: Разовая покупка в первый месяц
B47: Прочие стартовые расходы | C47: 50000 | D47: ₽ | E47: Регистрация, сайт, депозит
B49: 7. ЮНИТ-ЭКОНОМИКА
...

Sheet 📈 Выручка
B2: 📈 ВЫРУЧКА
B3: Все расчёты автоматические. Данные берутся из листа ⚙️ Допущения
B5: ПРОДУКТ / УСЛУГА 1
B6: Показатель | C6: Янв | D6: Фев | E6: Мар | F6: Апр | G6: Май | H6: Июн | I6: Июл | J6: Авг | K6: Сен | L6: Окт | M6: Ноя | N6: Дек | O6: ИТОГО год
B7: Кол-во продаж, шт | C7: ='⚙️ Допущения'!C14 -> 300 | D7: =ROUND(C7*(1+'⚙️ Допущения'!C15),0) -> 315 | E7: =ROUND(D7*(1+'⚙️ Допущения'!C15),0) -> 331 | F7: =ROUND(E7*(1+'⚙️ Допущения'!C15),0) -> 348 | G7: =ROUND(F7*(1+'⚙️ Допущения'!C15),0) -> 365 | H7: =ROUND(G7*(1+'⚙️ Допущения'!C15),0) -> 383 | I7: =ROUND(H7*(1+'⚙️ Допущения'!C15),0) -> 402 | J7: =ROUND(I7*(1+'⚙️ Допущения'!C15),0) -> 422 | K7: =ROUND(J7*(1+'⚙️ Допущения'!C15),0) -> 443 | L7: =ROUND(K7*(1+'⚙️ Допущения'!C15),0) -> 465 | M7: =ROUND(L7*(1+'⚙️ Допущения'!C15),0) -> 488 | N7: =ROUND(M7*(1+'⚙️ Допущения'!C15),0) -> 512 | O7: =SUM(C7:N7) -> 4774
B8: Выручка, ₽ | C8: =C7*'⚙️ Допущения'!C13 -> 1500000 | D8: =D7*'⚙️ Допущения'!C13 -> 1575000 | E8: =E7*'⚙️ Допущения'!C13 -> 1655000 | F8: =F7*'⚙️ Допущения'!C13 -> 1740000 | G8: =G7*'⚙️ Допущения'!C13 -> 1825000 | H8: =H7*'⚙️ Допущения'!C13 -> 1915000 | I8: =I7*'⚙️ Допущения'!C13 -> 2010000 | J8: =J7*'⚙️ Допущения'!C13 -> 2110000 | K8: =K7*'⚙️ Допущения'!C13 -> 2215000 | L8: =L7*'⚙️ Допущения'!C13 -> 2325000 | M8: =M7*'⚙️ Допущения'!C13 -> 2440000 | N8: =N7*'⚙️ Допущения'!C13 -> 2560000 | O8: =SUM(C8:N8) -> 23870000
B11: ПРОДУКТ / УСЛУГА 2
B12: Показатель | C12: Янв | D12: Фев | E12: Мар | F12: Апр | G12: Май | H12: Июн | I12: Июл | J12: Авг | K12: Сен | L12: Окт | M12: Ноя | N12: Дек | O12: ИТОГО год
B13: Кол-во продаж, шт | C13: ='⚙️ Допущения'!C20 -> 0 | D13: =ROUND(C13*(1+'⚙️ Допущения'!C21),0) -> 0 | E13: =ROUND(D13*(1+'⚙️ Допущения'!C21),0) -> 0 | F13: =ROUND(E13*(1+'⚙️ Допущения'!C21),0) -> 0 | G13: =ROUND(F13*(1+'⚙️ Допущения'!C21),0) -> 0 | H13: =ROUND(G13*(1+'⚙️ Допущения'!C21),0) -> 0 | I13: =ROUND(H13*(1+'⚙️ Допущения'!C21),0) -> 0 | J13: =ROUND(I13*(1+'⚙️ Допущения'!C21),0) -> 0 | K13: =ROUND(J13*(1+'⚙️ Допущения'!C21),0) -> 0 | L13: =ROUND(K13*(1+'⚙️ Допущения'!C21),0) -> 0 | M13: =ROUND(L13*(1+'⚙️ Допущения'!C21),0) -> 0 | N13: =ROUND(M13*(1+'⚙️ Допущения'!C21),0) -> 0 | O13: =SUM(C13:N13) -> 0
B14: Выручка, ₽ | C14: =C13*'⚙️ Допущения'!C19 -> 0 | D14: =D13*'⚙️ Допущения'!C19 -> 0 | E14: =E13*'⚙️ Допущения'!C19 -> 0 | F14: =F13*'⚙️ Допущения'!C19 -> 0 | G14: =G13*'⚙️ Допущения'!C19 -> 0 | H14: =H13*'⚙️ Допущения'!C19 -> 0 | I14: =I13*'⚙️ Допущения'!C19 -> 0 | J14: =J13*'⚙️ Допущения'!C19 -> 0 | K14: =K13*'⚙️ Допущения'!C19 -> 0 | L14: =L13*'⚙️ Допущения'!C19 -> 0 | M14: =M13*'⚙️ Допущения'!C19 -> 0 | N14: =N13*'⚙️ Допущения'!C19 -> 0 | O14: =SUM(C14:N14) -> 0
B17: ИТОГО ВЫРУЧКА
B18: ИТОГО ВЫРУЧКА, ₽ | C18: =C8+C14 -> 1500000 | D18: =D8+D14 -> 1575000 | E18: =E8+E14 -> 1655000 | F18: =F8+F14 -> 1740000 | G18: =G8+G14 -> 1825000 | H18: =H8+H14 -> 1915000 | I18: =I8+I14 -> 2010000 | J18: =J8+J14 -> 2110000 | ... N18: =N8+N14 -> 2560000 | O18: =SUM(C18:N18) -> 23870000
B19: ИТОГО продаж, шт | C19: =C7+C13 -> 300 | D19: =D7+D13 -> 315 | E19: =E7+E13 -> 331 | F19: =F7+F13 -> 348 | G19: =G7+G13 -> 365 | H19: =H7+H13 -> 383 | I19: =I7+I13 -> 402 | J19: =J7+J13 -> 422 | ... N19: =N7+N13 -> 512 | O19: =SUM(C19:N19) -> 4774

Sheet 💸 Расходы
B2: 💸 РАСХОДЫ
B3: Постоянные расходы + переменные (% от выручки). Все данные из листа Допущения
B5: ПОСТОЯННЫЕ РАСХОДЫ
B6: Показатель | C6: Янв | D6: Фев | E6: Мар | F6: Апр | G6: Май | H6: Июн | I6: Июл | J6: Авг | K6: Сен | L6: Окт | M6: Ноя | N6: Дек | O6: ИТОГО год
B7: Аренда | C7: ='⚙️ Допущения'!C25 -> 50000 | D7: =C7*(1+'⚙️ Допущения'!C30) -> 51000 | E7: =D7*(1+'⚙️ Допущения'!C30) -> 52020 | F7: =E7*(1+'⚙️ Допущения'!C30) -> 53060.4 | G7: =F7*(1+'⚙️ Допущения'!C30) -> 54121.608 | H7: =G7*(1+'⚙️ Допущения'!C30) -> 55204.04 | I7: =H7*(1+'⚙️ Допущения'!C30) -> 56308.121 | J7: =I7*(1+'⚙️ Допущения'!C30) -> 57434.283 | K7: =J7*(1+'⚙️ Допущения'!C30) -> 58582.969 | L7: =K7*(1+'⚙️ Допущения'!C30) -> 59754.628 | M7: =L7*(1+'⚙️ Допущения'!C30) -> 60949.721 | N7: =M7*(1+'⚙️ Допущения'!C30) -> 62168.715 | O7: =SUM(C7:N7) -> 670604.49
B8: ФОТ | C8: ='⚙️ Допущения'!C26 -> 200000 | D8: =C8*(1+'⚙️ Допущения'!C30) -> 204000 | E8: =D8*(1+'⚙️ Допущения'!C30) -> 208080 | F8: =E8*(1+'⚙️ Допущения'!C30) -> 212241.6 | G8: =F8*(1+'⚙️ Допущения'!C30) -> 216486.43 | H8: =G8*(1+'⚙️ Допущения'!C30) -> 220816.16 | I8: =H8*(1+'⚙️ Допущения'!C30) -> 225232.48 | J8: =I8*(1+'⚙️ Допущения'!C30) -> 229737.13 | K8: =J8*(1+'⚙️ Допущения'!C30) -> 234331.88 | L8: =K8*(1+'⚙️ Допущения'!C30) -> 239018.51 | M8: =L8*(1+'⚙️ Допущения'!C30) -> 243798.88 | N8: =M8*(1+'⚙️ Допущения'!C30) -> 248674.86 | O8: =SUM(C8:N8) -> 2682417.9
B9: Маркетинг (фикс.) | C9: ='⚙️ Допущения'!C27 -> 30000 | D9: =C9*(1+'⚙️ Допущения'!C30) -> 30600 | E9: =D9*(1+'⚙️ Допущения'!C30) -> 31212 | F9: =E9*(1+'⚙️ Допущения'!C30) -> 31836.24 | G9: =F9*(1+'⚙️ Допущения'!C30) -> 32472.965 | H9: =G9*(1+'⚙️ Допущения'!C30) -> 33122.424 | I9: =H9*(1+'⚙️ Допущения'!C30) -> 33784.873 | J9: =I9*(1+'⚙️ Допущения'!C30) -> 34460.57 | K9: =J9*(1+'⚙️ Допущения'!C30) -> 35149.781 | L9: =K9*(1+'⚙️ Допущения'!C30) -> 35852.777 | M9: =L9*(1+'⚙️ Допущения'!C30) -> 36569.833 | N9: =M9*(1+'⚙️ Допущения'!C30) -> 37301.229 | O9: =SUM(C9:N9) -> 402362.69
B10: ПО и подписки | C10: ='⚙️ Допущения'!C28 -> 10000 | D10: =C10*(1+'⚙️ Допущения'!C30) -> 10200 | E10: =D10*(1+'⚙️ Допущения'!C30) -> 10404 | F10: =E10*(1+'⚙️ Допущения'!C30) -> 10612.08 | G10: =F10*(1+'⚙️ Допущения'!C30) -> 10824.322 | H10: =G10*(1+'⚙️ Допущения'!C30) -> 11040.808 | I10: =H10*(1+'⚙️ Допущения'!C30) -> 11261.624 | J10: =I10*(1+'⚙️ Допущения'!C30) -> 11486.857 | K10: =J10*(1+'⚙️ Допущения'!C30) -> 11716.594 | L10: =K10*(1+'⚙️ Допущения'!C30) -> 11950.926 | M10: =L10*(1+'⚙️ Допущения'!C30) -> 12189.944 | N10: =M10*(1+'⚙️ Допущения'!C30) -> 12433.743 | O10: =SUM(C10:N10) -> 134120.9
B11: Прочие постоянные | C11: ='⚙️ Допущения'!C29 -> 20000 | D11: =C11*(1+'⚙️ Допущения'!C30) -> 20400 | E11: =D11*(1+'⚙️ Допущения'!C30) -> 20808 | F11: =E11*(1+'⚙️ Допущения'!C30) -> 21224.16 | G11: =F11*(1+'⚙️ Допущения'!C30) -> 21648.643 | H11: =G11*(1+'⚙️ Допущения'!C30) -> 22081.616 | I11: =H11*(1+'⚙️ Допущения'!C30) -> 22523.248 | J11: =I11*(1+'⚙️ Допущения'!C30) -> 22973.713 | K11: =J11*(1+'⚙️ Допущения'!C30) -> 23433.188 | L11: =K11*(1+'⚙️ Допущения'!C30) -> 23901.851 | M11: =L11*(1+'⚙️ Допущения'!C30) -> 24379.888 | N11: =M11*(1+'⚙️ Допущения'!C30) -> 24867.486 | O11: =SUM(C11:N11) -> 268241.79
B13: ИТОГО постоянные | C13: =SUM(C7:C11) -> 310000 | D13: =SUM(D7:D11) -> 316200 | E13: =SUM(E7:E11) -> 322524 | F13: =SUM(F7:F11) -> 328974.48 | G13: =SUM(G7:G11) -> 335553.97 | H13: =SUM(H7:H11) -> 342265.05 | I13: =SUM(I7:I11) -> 349110.35 | J13: =SUM(J7:J11) -> 356092.56 | ... N13: =SUM(N7:N11) -> 385446.04 | O13: =SUM(C13:N13) -> 4157747.8
B16: ПЕРЕМЕННЫЕ РАСХОДЫ (% от выручки)
B17: Показатель | C17: Янв | D17: Фев | E17: Мар | F17: Апр | G17: Май | H17: Июн | I17: Июл | J17: Авг | K17: Сен | L17: Окт | M17: Ноя | N17: Дек | O17: ИТОГО год
B18: Себестоимость (COGS) | C18: ='📈 Выручка'!C18*'⚙️ Допущения'!C33 -> 450000 | D18: ='📈 Выручка'!D18*'⚙️ Допущения'!C33 -> 472500 | E18: ='📈 Выручка'!E18*'⚙️ Допущения'!C33 -> 496500 | F18: ='📈 Выручка'!F18*'⚙️ Допущения'!C33 -> 522000 | G18: ='📈 Выручка'!G18*'⚙️ Допущения'!C33 -> 547500 | H18: ='📈 Выручка'!H18*'⚙️ Допущения'!C33 -> 574500 | I18: ='📈 Выручка'!I18*'⚙️ Допущения'!C33 -> 603000 | J18: ='📈 Выручка'!J18*'⚙️ Допущения'!C33 -> 633000 | K18: ='📈 Выручка'!K18*'⚙️ Допущения'!C33 -> 664500 | L18: ='📈 Выручка'!L18*'⚙️ Допущения'!C33 -> 697500 | M18: ='📈 Выручка'!M18*'⚙️ Допущения'!C33 -> 732000 | N18: ='📈 Выручка'!N18*'⚙️ Допущения'!C33 -> 768000 | O18: =SUM(C18:N18) -> 7161000
B19: Эквайринг / комиссии | C19: ='📈 Выручка'!C18*'⚙️ Допущения'!C34 -> 30000 | D19: ='📈 Выручка'!D18*'⚙️ Допущения'!C34 -> 31500 | E19: ='📈 Выручка'!E18*'⚙️ Допущения'!C34 -> 33100 | F19: ='📈 Выручка'!F18*'⚙️ Допущения'!C34 -> 34800 | G19: ='📈 Выручка'!G18*'⚙️ Допущения'!C34 -> 36500 | H19: ='📈 Выручка'!H18*'⚙️ Допущения'!C34 -> 38300 | I19: ='📈 Выручка'!I18*'⚙️ Допущения'!C34 -> 40200 | J19: ='📈 Выручка'!J18*'⚙️ Допущения'!C34 -> 42200 | K19: ='📈 Выручка'!K18*'⚙️ Допущения'!C34 -> 44300 | L19: ='📈 Выручка'!L18*'⚙️ Допущения'!C34 -> 46500 | M19: ='📈 Выручка'!M18*'⚙️ Допущения'!C34 -> 48800 | N19: ='📈 Выручка'!N18*'⚙️ Допущения'!C34 -> 51200 | O19: =SUM(C19:N19) -> 477400
B20: Переменный маркетинг | C20: ='📈 Выручка'!C18*'⚙️ Допущения'!C35 -> 75000 | D20: ='📈 Выручка'!D18*'⚙️ Допущения'!C35 -> 78750 | E20: ='📈 Выручка'!E18*'⚙️ Допущения'!C35 -> 82750 | F20: ='📈 Выручка'!F18*'⚙️ Допущения'!C35 -> 87000 | G20: ='📈 Выручка'!G18*'⚙️ Допущения'!C35 -> 91250 | H20: ='📈 Выручка'!H18*'⚙️ Допущения'!C35 -> 95750 | I20: ='📈 Выручка'!I18*'⚙️ Допущения'!C35 -> 100500 | J20: ='📈 Выручка'!J18*'⚙️ Допущения'!C35 -> 105500 | K20: ='📈 Выручка'!K18*'⚙️ Допущения'!C35 -> 110750 | L20: ='📈 Выручка'!L18*'⚙️ Допущения'!C35 -> 116250 | M20: ='📈 Выручка'!M18*'⚙️ Допущения'!C35 -> 122000 | N20: ='📈 Выручка'!N18*'⚙️ Допущения'!C35 -> 128000 | O20: =SUM(C20:N20) -> 1193500
B21: Прочие переменные | C21: ='📈 Выручка'!C18*'⚙️ Допущения'!C36 -> 45000 | D21: ='📈 Выручка'!D18*'⚙️ Допущения'!C36 -> 47250 | E21: ='📈 Выручка'!E18*'⚙️ Допущения'!C36 -> 49650 | F21: ='📈 Выручка'!F18*'⚙️ Допущения'!C36 -> 52200 | G21: ='📈 Выручка'!G18*'⚙️ Допущения'!C36 -> 54750 | H21: ='📈 Выручка'!H18*'⚙️ Допущения'!C36 -> 57450 | I21: ='📈 Выручка'!I18*'⚙️ Допущения'!C36 -> 60300 | J21: ='📈 Выручка'!J18*'⚙️ Допущения'!C36 -> 63300 | K21: ='📈 Выручка'!K18*'⚙️ Допущения'!C36 -> 66450 | L21: ='📈 Выручка'!L18*'⚙️ Допущения'!C36 -> 69750 | M21: ='📈 Выручка'!M18*'⚙️ Допущения'!C36 -> 73200 | N21: ='📈 Выручка'!N18*'⚙️ Допущения'!C36 -> 76800 | O21: =SUM(C21:N21) -> 716100
B23: ИТОГО переменные | C23: =SUM(C18:C21) -> 600000 | D23: =SUM(D18:D21) -> 630000 | E23: =SUM(E18:E21) -> 662000 | F23: =SUM(F18:F21) -> 696000 | G23: =SUM(G18:G21) -> 730000 | H23: =SUM(H18:H21) -> 766000 | I23: =SUM(I18:I21) -> 804000 | J23: =SUM(J18:J21) -> 844000 | ... N23: =SUM(N18:N21) -> 1024000 | O23: =SUM(C23:N23) -> 9548000
B26: ИТОГО РАСХОДЫ
B27: ИТОГО ВСЕ РАСХОДЫ | C27: =C13+C23 -> 910000 | D27: =D13+D23 -> 946200 | E27: =E13+E23 -> 984524 | F27: =F13+F23 -> 1024974.5 | G27: =G13+G23 -> 1065554 | H27: =H13+H23 -> 1108265 | I27: =I13+I23 -> 1153110.4 | J27: =J13+J23 -> 1200092.6 | ... N27: =N13+N23 -> 1409446 | O27: =SUM(C27:N27) -> 13705748

Sheet 📊 ОПУ
B2: 📊 ОПУ — ОТЧЁТ О ПРИБЫЛЯХ И УБЫТКАХ
B4: Показатель | C4: Янв | D4: Фев | E4: Мар | F4: Апр | G4: Май | H4: Июн | I4: Июл | J4: Авг | K4: Сен | L4: Окт | M4: Ноя | N4: Дек | O4: ИТОГО год
B5: ВЫРУЧКА | C5: ='📈 Выручка'!C18 -> 1500000 | D5: ='📈 Выручка'!D18 -> 1575000 | E5: ='📈 Выручка'!E18 -> 1655000 | F5: ='📈 Выручка'!F18 -> 1740000 | G5: ='📈 Выручка'!G18 -> 1825000 | H5: ='📈 Выручка'!H18 -> 1915000 | I5: ='📈 Выручка'!I18 -> 2010000 | J5: ='📈 Выручка'!J18 -> 2110000 | ... N5: ='📈 Выручка'!N18 -> 2560000 | O5: =SUM(C5:N5) -> 23870000
B6: — Себестоимость (COGS) | C6: ='💸 Расходы'!C18 -> 450000 | D6: ='💸 Расходы'!D18 -> 472500 | E6: ='💸 Расходы'!E18 -> 496500 | F6: ='💸 Расходы'!F18 -> 522000 | G6: ='💸 Расходы'!G18 -> 547500 | H6: ='💸 Расходы'!H18 -> 574500 | I6: ='💸 Расходы'!I18 -> 603000 | J6: ='💸 Расходы'!J18 -> 633000 | ... N6: ='💸 Расходы'!N18 -> 768000 | O6: =SUM(C6:N6) -> 7161000
B7: ВАЛОВАЯ ПРИБЫЛЬ | C7: =C5-C6 -> 1050000 | D7: =D5-D6 -> 1102500 | E7: =E5-E6 -> 1158500 | F7: =F5-F6 -> 1218000 | G7: =G5-G6 -> 1277500 | H7: =H5-H6 -> 1340500 | I7: =I5-I6 -> 1407000 | J7: =J5-J6 -> 1477000 | ... N7: =N5-N6 -> 1792000 | O7: =SUM(C7:N7) -> 16709000
B8: Валовая маржа, % | C8: =IFERROR(C7/C5,0) -> 0.7 | D8: =IFERROR(D7/D5,0) -> 0.7 | E8: =IFERROR(E7/E5,0) -> 0.7 | F8: =IFERROR(F7/F5,0) -> 0.7 | G8: =IFERROR(G7/G5,0) -> 0.7 | H8: =IFERROR(H7/H5,0) -> 0.7 | I8: =IFERROR(I7/I5,0) -> 0.7 | J8: =IFERROR(J7/J5,0) -> 0.7 | ... N8: =IFERROR(N7/N5,0) -> 0.7 | O8: —
B9: — Маркетинг (перем.) | C9: ='💸 Расходы'!C20 -> 75000 | D9: ='💸 Расходы'!D20 -> 78750 | E9: ='💸 Расходы'!E20 -> 82750 | F9: ='💸 Расходы'!F20 -> 87000 | G9: ='💸 Расходы'!G20 -> 91250 | H9: ='💸 Расходы'!H20 -> 95750 | I9: ='💸 Расходы'!I20 -> 100500 | J9: ='💸 Расходы'!J20 -> 105500 | ... N9: ='💸 Расходы'!N20 -> 128000 | O9: =SUM(C9:N9) -> 1193500
B10: — Эквайринг | C10: ='💸 Расходы'!C19 -> 30000 | D10: ='💸 Расходы'!D19 -> 31500 | E10: ='💸 Расходы'!E19 -> 33100 | F10: ='💸 Расходы'!F19 -> 34800 | G10: ='💸 Расходы'!G19 -> 36500 | H10: ='💸 Расходы'!H19 -> 38300 | I10: ='💸 Расходы'!I19 -> 40200 | J10: ='💸 Расходы'!J19 -> 42200 | ... N10: ='💸 Расходы'!N19 -> 51200 | O10: =SUM(C10:N10) -> 477400
B11: — Прочие переменные | C11: ='💸 Расходы'!C21 -> 45000 | D11: ='💸 Расходы'!D21 -> 47250 | E11: ='💸 Расходы'!E21 -> 49650 | F11: ='💸 Расходы'!F21 -> 52200 | G11: ='💸 Расходы'!G21 -> 54750 | H11: ='💸 Расходы'!H21 -> 57450 | I11: ='💸 Расходы'!I21 -> 60300 | J11: ='💸 Расходы'!J21 -> 63300 | ... N11: ='💸 Расходы'!N21 -> 76800 | O11: =SUM(C11:N11) -> 716100
B12: — Аренда | C12: ='💸 Расходы'!C7 -> 50000 | D12: ='💸 Расходы'!D7 -> 51000 | E12: ='💸 Расходы'!E7 -> 52020 | F12: ='💸 Расходы'!F7 -> 53060.4 | G12: ='💸 Расходы'!G7 -> 54121.608 | H12: ='💸 Расходы'!H7 -> 55204.04 | I12: ='💸 Расходы'!I7 -> 56308.121 | J12: ='💸 Расходы'!J7 -> 57434.283 | ... N12: ='💸 Расходы'!N7 -> 62168.715 | O12: =SUM(C12:N12) -> 670604.49
B13: — ФОТ | C13: ='💸 Расходы'!C8 -> 200000 | D13: ='💸 Расходы'!D8 -> 204000 | E13: ='💸 Расходы'!E8 -> 208080 | F13: ='💸 Расходы'!F8 -> 212241.6 | G13: ='💸 Расходы'!G8 -> 216486.43 | H13: ='💸 Расходы'!H8 -> 220816.16 | I13: ='💸 Расходы'!I8 -> 225232.48 | J13: ='💸 Расходы'!J8 -> 229737.13 | ... N13: ='💸 Расходы'!N8 -> 248674.86 | O13: =SUM(C13:N13) -> 2682417.9
B14: — Маркетинг (фикс.) | C14: ='💸 Расходы'!C9 -> 30000 | D14: ='💸 Расходы'!D9 -> 30600 | E14: ='💸 Расходы'!E9 -> 31212 | F14: ='💸 Расходы'!F9 -> 31836.24 | G14: ='💸 Расходы'!G9 -> 32472.965 | H14: ='💸 Расходы'!H9 -> 33122.424 | I14: ='💸 Расходы'!I9 -> 33784.873 | J14: ='💸 Расходы'!J9 -> 34460.57 | ... N14: ='💸 Расходы'!N9 -> 37301.229 | O14: =SUM(C14:N14) -> 402362.69
B15: — ПО и подписки | C15: ='💸 Расходы'!C10 -> 10000 | D15: ='💸 Расходы'!D10 -> 10200 | E15: ='💸 Расходы'!E10 -> 10404 | F15: ='💸 Расходы'!F10 -> 10612.08 | G15: ='💸 Расходы'!G10 -> 10824.322 | H15: ='💸 Расходы'!H10 -> 11040.808 | I15: ='💸 Расходы'!I10 -> 11261.624 | J15: ='💸 Расходы'!J10 -> 11486.857 | ... N15: ='💸 Расходы'!N10 -> 12433.743 | O15: =SUM(C15:N15) -> 134120.9
B16: — Прочие постоянные | C16: ='💸 Расходы'!C11 -> 20000 | D16: ='💸 Расходы'!D11 -> 20400 | E16: ='💸 Расходы'!E11 -> 20808 | F16: ='💸 Расходы'!F11 -> 21224.16 | G16: ='💸 Расходы'!G11 -> 21648.643 | H16: ='💸 Расходы'!H11 -> 22081.616 | I16: ='💸 Расходы'!I11 -> 22523.248 | J16: ='💸 Расходы'!J11 -> 22973.713 | ... N16: ='💸 Расходы'!N11 -> 24867.486 | O16: =SUM(C16:N16) -> 268241.79
B17: EBITDA | C17: =C7-SUM(C9:C16) -> 590000 | D17: =D7-SUM(D9:D16) -> 628800 | E17: =E7-SUM(E9:E16) -> 670476 | F17: =F7-SUM(F9:F16) -> 715025.52 | G17: =G7-SUM(G9:G16) -> 759446.03 | H17: =H7-SUM(H9:H16) -> 806734.95 | I17: =I7-SUM(I9:I16) -> 856889.65 | J17: =J7-SUM(J9:J16) -> 909907.44 | ... N17: =N7-SUM(N9:N16) -> 1150554 | O17: =SUM(C17:N17) -> 10164252
B18: EBITDA маржа, % | C18: =IFERROR(C17/C5,0) -> 0.39333333 | D18: =IFERROR(D17/D5,0) -> 0.3992381 | E18: =IFERROR(E17/E5,0) -> 0.40512145 | F18: =IFERROR(F17/F5,0) -> 0.41093421 | G18: =IFERROR(G17/G5,0) -> 0.41613481 | H18: =IFERROR(H17/H5,0) -> 0.42127151 | I18: =IFERROR(I17/I5,0) -> 0.42631326 | J18: =IFERROR(J17/J5,0) -> 0.43123575 | ... N18: =IFERROR(N17/N5,0) -> 0.44943514 | O18: —
B19: — Налог (УСН 6%) | C19: =MAX(0,C5*'⚙️ Допущения'!C40) -> 90000 | D19: =MAX(0,D5*'⚙️ Допущения'!C40) -> 94500 | E19: =MAX(0,E5*'⚙️ Допущения'!C40) -> 99300 | F19: =MAX(0,F5*'⚙️ Допущения'!C40) -> 104400 | G19: =MAX(0,G5*'⚙️ Допущения'!C40) -> 109500 | H19: =MAX(0,H5*'⚙️ Допущения'!C40) -> 114900 | I19: =MAX(0,I5*'⚙️ Допущения'!C40) -> 120600 | J19: =MAX(0,J5*'⚙️ Допущения'!C40) -> 126600 | K19: =MAX(0,K5*'⚙️ Допущения'!C40) -> 132900 | L19: =MAX(0,L5*'⚙️ Допущения'!C40) -> 139500 | M19: =MAX(0,M5*'⚙️ Допущения'!C40) -> 146400 | N19: =MAX(0,N5*'⚙️ Допущения'!C40) -> 153600 | O19: =SUM(C19:N19) -> 1432200
B20: ЧИСТАЯ ПРИБЫЛЬ | C20: =C17-C19 -> 500000 | D20: =D17-D19 -> 534300 | E20: =E17-E19 -> 571176 | F20: =F17-F19 -> 610625.52 | G20: =G17-G19 -> 649946.03 | H20: =H17-H19 -> 691834.95 | I20: =I17-I19 -> 736289.65 | J20: =J17-J19 -> 783307.44 | ... N20: =N17-N19 -> 996953.96 | O20: =SUM(C20:N20) -> 8732052.2
B21: Чистая маржа, % | C21: =IFERROR(C20/C5,0) -> 0.33333333 | D21: =IFERROR(D20/D5,0) -> 0.3392381 | E21: =IFERROR(E20/E5,0) -> 0.34512145 | F21: =IFERROR(F20/F5,0) -> 0.35093421 | G21: =IFERROR(G20/G5,0) -> 0.35613481 | H21: =IFERROR(H20/H5,0) -> 0.36127151 | I21: =IFERROR(I20/I5,0) -> 0.36631326 | J21: =IFERROR(J20/J5,0) -> 0.37123576 | ... N21: =IFERROR(N20/N5,0) -> 0.38943514 | O21: —

Sheet 💰 ДДС
B2: 💰 ДДС — ДВИЖЕНИЕ ДЕНЕЖНЫХ СРЕДСТВ
B3: ⚠️ Кассовый разрыв = остаток на конец месяца < 0. Следите за строкой 'Остаток на конец'!
B5: Показатель | C5: Янв | D5: Фев | E5: Мар | F5: Апр | G5: Май | H5: Июн | I5: Июл | J5: Авг | K5: Сен | L5: Окт | M5: Ноя | N5: Дек | O5: ИТОГО год
B6: ОСТАТОК НА НАЧАЛО | C6: ='⚙️ Допущения'!C45 -> 500000 | D6: =C25 -> 880000 | E6: =D25 -> 1445800 | F6: =E25 -> 2050076 | G6: =F25 -> 2695501.5 | H6: =G25 -> 3381947.5 | I6: =H25 -> 4112082.5 | J6: =I25 -> 4888572.2 | K6: =J25 -> 5714079.6 | ... N6: =M25 -> 8511298.2
B7: ПОСТУПЛЕНИЯ (операц.) | C7: =C8 -> 1500000 | D7: =D8 -> 1575000 | E7: =E8 -> 1655000 | F7: =F8 -> 1740000 | G7: =G8 -> 1825000 | H7: =H8 -> 1915000 | I7: =I8 -> 2010000 | J7: =J8 -> 2110000 | ... N7: =N8 -> 2560000 | O7: =SUM(C7:N7) -> 23870000
B8: + Оплаты от клиентов | C8: ='📈 Выручка'!C18 -> 1500000 | D8: ='📈 Выручка'!D18 -> 1575000 | E8: ='📈 Выручка'!E18 -> 1655000 | F8: ='📈 Выручка'!F18 -> 1740000 | G8: ='📈 Выручка'!G18 -> 1825000 | H8: ='📈 Выручка'!H18 -> 1915000 | I8: ='📈 Выручка'!I18 -> 2010000 | J8: ='📈 Выручка'!J18 -> 2110000 | ... N8: ='📈 Выручка'!N18 -> 2560000
B9: ВЫПЛАТЫ (операц.) | C9: =SUM(C10:C16) -> 970000 | D9: =SUM(D10:D16) -> 1009200 | E9: =SUM(E10:E16) -> 1050724 | F9: =SUM(F10:F16) -> 1094574.5 | G9: =SUM(G10:G16) -> 1138554 | H9: =SUM(H10:H16) -> 1184865 | I9: =SUM(I10:I16) -> 1233510.4 | J9: =SUM(J10:J16) -> 1284492.6 | ... N9: =SUM(N10:N16) -> 1511846 | O9: =SUM(C9:N9) -> 14660548
B10: — Себестоимость | C10: ='💸 Расходы'!C18 -> 450000 | D10: ='💸 Расходы'!D18 -> 472500 | E10: ='💸 Расходы'!E18 -> 496500 | F10: ='💸 Расходы'!F18 -> 522000 | G10: ='💸 Расходы'!G18 -> 547500 | H10: ='💸 Расходы'!H18 -> 574500 | I10: ='💸 Расходы'!I18 -> 603000 | J10: ='💸 Расходы'!J18 -> 633000 | ... N10: ='💸 Расходы'!N18 -> 768000
B11: — Аренда | C11: ='💸 Расходы'!C7 -> 50000 | D11: ='💸 Расходы'!D7 -> 51000 | E11: ='💸 Расходы'!E7 -> 52020 | F11: ='💸 Расходы'!F7 -> 53060.4 | G11: ='💸 Расходы'!G7 -> 54121.608 | H11: ='💸 Расходы'!H7 -> 55204.04 | I11: ='💸 Расходы'!I7 -> 56308.121 | J11: ='💸 Расходы'!J7 -> 57434.283 | ... N11: ='💸 Расходы'!N7 -> 62168.715
B12: — ФОТ | C12: ='💸 Расходы'!C8 -> 200000 | D12: ='💸 Расходы'!D8 -> 204000 | E12: ='💸 Расходы'!E8 -> 208080 | F12: ='💸 Расходы'!F8 -> 212241.6 | G12: ='💸 Расходы'!G8 -> 216486.43 | H12: ='💸 Расходы'!H8 -> 220816.16 | I12: ='💸 Расходы'!I8 -> 225232.48 | J12: ='💸 Расходы'!J8 -> 229737.13 | ... N12: ='💸 Расходы'!N8 -> 248674.86
B13: — Маркетинг | C13: ='💸 Расходы'!C9+'💸 Расходы'!C20 -> 105000 | D13: ='💸 Расходы'!D9+'💸 Расходы'!D20 -> 109350 | E13: ='💸 Расходы'!E9+'💸 Расходы'!E20 -> 113962 | F13: ='💸 Расходы'!F9+'💸 Расходы'!F20 -> 118836.24 | G13: ='💸 Расходы'!G9+'💸 Расходы'!G20 -> 123722.96 | H13: ='💸 Расходы'!H9+'💸 Расходы'!H20 -> 128872.42 | I13: ='💸 Расходы'!I9+'💸 Расходы'!I20 -> 134284.87 | J13: ='💸 Расходы'!J9+'💸 Расходы'!J20 -> 139960.57 | ... N13: ='💸 Расходы'!N9+'💸 Расходы'!N20 -> 165301.23
B14: — ПО и подписки | C14: ='💸 Расходы'!C10 -> 10000 | D14: ='💸 Расходы'!D10 -> 10200 | E14: ='💸 Расходы'!E10 -> 10404 | F14: ='💸 Расходы'!F10 -> 10612.08 | G14: ='💸 Расходы'!G10 -> 10824.322 | H14: ='💸 Расходы'!H10 -> 11040.808 | I14: ='💸 Расходы'!I10 -> 11261.624 | J14: ='💸 Расходы'!J10 -> 11486.857 | ... N14: ='💸 Расходы'!N10 -> 12433.743
B15: — Прочие расходы | C15: ='💸 Расходы'!C11+'💸 Расходы'!C21 -> 65000 | D15: ='💸 Расходы'!D11+'💸 Расходы'!D21 -> 67650 | E15: ='💸 Расходы'!E11+'💸 Расходы'!E21 -> 70458 | F15: ='💸 Расходы'!F11+'💸 Расходы'!F21 -> 73424.16 | G15: ='💸 Расходы'!G11+'💸 Расходы'!G21 -> 76398.643 | H15: ='💸 Расходы'!H11+'💸 Расходы'!H21 -> 79531.616 | I15: ='💸 Расходы'!I11+'💸 Расходы'!I21 -> 82823.248 | J15: ='💸 Расходы'!J11+'💸 Расходы'!J21 -> 86273.713 | ... N15: ='💸 Расходы'!N11+'💸 Расходы'!N21 -> 101667.49
B16: — Налог (УСН) | C16: ='📊 ОПУ'!C19 -> 90000 | D16: ='📊 ОПУ'!D19 -> 94500 | E16: ='📊 ОПУ'!E19 -> 99300 | F16: ='📊 ОПУ'!F19 -> 104400 | G16: ='📊 ОПУ'!G19 -> 109500 | H16: ='📊 ОПУ'!H19 -> 114900 | I16: ='📊 ОПУ'!I19 -> 120600 | J16: ='📊 ОПУ'!J19 -> 126600 | ... N16: ='📊 ОПУ'!N19 -> 153600
B17: ОПЕРАЦИОННЫЙ ПОТОК (OCF) | C17: =C7-C9 -> 530000 | D17: =D7-D9 -> 565800 | E17: =E7-E9 -> 604276 | F17: =F7-F9 -> 645425.52 | G17: =G7-G9 -> 686446.03 | H17: =H7-H9 -> 730134.95 | I17: =I7-I9 -> 776489.65 | J17: =J7-J9 -> 825507.44 | ... N17: =N7-N9 -> 1048154 | O17: =SUM(C17:N17) -> 9209452.2
B18: ИНВЕСТИЦИОННЫЙ ПОТОК (ICF) | C18: =-C19-C20 -> -150000 | D18: =-D19-D20 -> 0 | E18: =-E19-E20 -> 0 | F18: =-F19-F20 -> 0 | G18: =-G19-G20 -> 0 | H18: =-H19-H20 -> 0 | I18: =-I19-I20 -> 0 | J18: =-J19-J20 -> 0 | ... N18: =-N19-N20 -> 0 | O18: =SUM(C18:N18) -> -150000
B19: — Покупка оборудования | C19: ='⚙️ Допущения'!C46+'⚙️ Допущения'!C47 -> 150000 | D19: 0 | E19: 0 | F19: 0 | G19: 0 | H19: 0 | I19: 0 | J19: 0 | K19: 0 | L19: 0 | M19: 0 | N19: 0
B20: — Прочие инвестиции | C20: 0 | D20: 0 | E20: 0 | F20: 0 | G20: 0 | H20: 0 | I20: 0 | J20: 0 | K20: 0 | L20: 0 | M20: 0 | N20: 0
B21: ФИНАНСОВЫЙ ПОТОК (FCF) | C21: =C22-C23 -> 0 | D21: =D22-D23 -> 0 | E21: =E22-E23 -> 0 | F21: =F22-F23 -> 0 | G21: =G22-G23 -> 0 | H21: =H22-H23 -> 0 | I21: =I22-I23 -> 0 | J21: =J22-J23 -> 0 | ... N21: =N22-N23 -> 0 | O21: =SUM(C21:N21) -> 0
B22: + Займы / кредиты | C22: 0 | D22: 0 | E22: 0 | F22: 0 | G22: 0 | H22: 0 | I22: 0 | J22: 0 | K22: 0 | L22: 0 | M22: 0 | N22: 0
B23: — Погашение долгов | C23: 0 | D23: 0 | E23: 0 | F23: 0 | G23: 0 | H23: 0 | I23: 0 | J23: 0 | K23: 0 | L23: 0 | M23: 0 | N23: 0
B24: ИТОГО ПОТОК ЗА МЕСЯЦ | C24: =C17+C18+C21 -> 380000 | D24: =D17+D18+D21 -> 565800 | E24: =E17+E18+E21 -> 604276 | F24: =F17+F18+F21 -> 645425.52 | G24: =G17+G18+G21 -> 686446.03 | H24: =H17+H18+H21 -> 730134.95 | I24: =I17+I18+I21 -> 776489.65 | J24: =J17+J18+J21 -> 825507.44 | ... N24: =N17+N18+N21 -> 1048154 | O24: =SUM(C24:N24) -> 9059452.2
B25: ОСТАТОК НА КОНЕЦ | C25: =C6+C24 -> 880000 | D25: =D6+D24 -> 1445800 | E25: =E6+E24 -> 2050076 | F25: =F6+F24 -> 2695501.5 | G25: =G6+G24 -> 3381947.5 | H25: =H6+H24 -> 4112082.5 | I25: =I6+I24 -> 4888572.2 | J25: =J6+J24 -> 5714079.6 | ... N25: =N6+N24 -> 9559452.2
B26: ⚠️ КАССОВЫЙ РАЗРЫВ? | C26: =IF(C25<0,"⚠️ РАЗРЫВ!","") | D26: =IF(D25<0,"⚠️ РАЗРЫВ!","") | E26: =IF(E25<0,"⚠️ РАЗРЫВ!","") | F26: =IF(F25<0,"⚠️ РАЗРЫВ!","") | G26: =IF(G25<0,"⚠️ РАЗРЫВ!","") | H26: =IF(H25<0,"⚠️ РАЗРЫВ!","") | I26: =IF(I25<0,"⚠️ РАЗРЫВ!","") | J26: =IF(J25<0,"⚠️ РАЗРЫВ!","") | ... N26: =IF(N25<0,"⚠️ РАЗРЫВ!","")

Sheet 🎯 Дашборд
B2: 🎯 ДАШБОРД — КЛЮЧЕВЫЕ МЕТРИКИ
B4: ВЫРУЧКА И ПРИБЫЛЬ (ГОД)
B5: Выручка за год | C5: ='📊 ОПУ'!O5 -> 23870000 | D5: Сумма всей выручки за 12 мес.
B6: Валовая прибыль за год | C6: ='📊 ОПУ'!O7 -> 16709000 | D6: После вычета себестоимости
B7: EBITDA за год | C7: ='📊 ОПУ'!O17 -> 10164252 | D7: До налогов и амортизации
B8: Чистая прибыль за год | C8: ='📊 ОПУ'!O20 -> 8732052.2 | D8: После всех расходов и налогов
B9: Валовая маржа | C9: =IFERROR('📊 ОПУ'!O7/'📊 ОПУ'!O5,0) -> 0.7 | D9: (Выручка − COGS) / Выручка
B10: Чистая маржа | C10: =IFERROR('📊 ОПУ'!O20/'📊 ОПУ'!O5,0) -> 0.36581702 | D10: Чистая прибыль / Выручка
B12: КЭШФЛОУ И ВЫЖИВАЕМОСТЬ
B13: Кэш на начало года | C13: ='💰 ДДС'!C6 -> 500000 | D13: Остаток на счёте в первый месяц
B14: Кэш на конец года | C14: ='💰 ДДС'!N25 -> 9559452.2 | D14: Остаток на счёте в декабре
B15: Минимальный остаток | C15: =MIN('💰 ДДС'!C25,'💰 ДДС'!D25,'💰 ДДС'!E25,'💰 ДДС'!F25,'💰 ДДС'!G25,'💰 ДДС'!H25,'💰 ДДС'!I25,'💰 ДДС'!J25,'💰 ДДС'!K25,'💰 ДДС'!L25,'💰 ДДС'!M25,'💰 ДДС'!N25) -> 880000 | D15: Наименьший остаток среди 12 мес. Должен быть > 0!
B16: Cash burn (среднемес.) | C16: =IFERROR(('💰 ДДС'!C6-'💰 ДДС'!N25)/12,0) -> -754954.35 | D16: Сколько сжигаем денег в месяц (если > 0 — убыточны)
B17: Runway (месяцев) | C17: =IFERROR(IF('💰 ДДС'!N25>0,">12",TEXT('💰 ДДС'!C6/MAX(1,('💰 ДДС'!C6-'💰 ДДС'!N25)/12),"0.0")),"н/д") -> >12 | D17: Сколько месяцев проживём без новых денег
B19: ЮНИТ-ЭКОНОМИКА
B20: CAC | C20: ='⚙️ Допущения'!C50 -> 1500 | D20: Стоимость привлечения 1 клиента (из допущений)
B21: LTV (расчётный) | C21: ='⚙️ Допущения'!C53*'⚙️ Допущения'!C13*'⚙️ Допущения'!C51*'⚙️ Допущения'!C52 -> 16000 | D21: Маржа × Чек × Частота × Срок жизни
B22: LTV / CAC | C22: =IFERROR(('⚙️ Допущения'!C53*'⚙️ Допущения'!C13*'⚙️ Допущения'!C51*'⚙️ Допущения'!C52)/'⚙️ Допущения'!C50,0) -> 10.666667 | D22: Норма: > 3x. Если < 1x — бизнес-модель убыточна на клиенте
B24: ТОЧКА БЕЗУБЫТОЧНОСТИ
B25: Постоянные расходы/мес. (ср) | C25: ='💸 Расходы'!O13/12 -> 346478.98 | D25: Среднемесячные постоянные расходы за год
B26: Маржинальность продукта | C26: ='⚙️ Допущения'!C53 -> 0.4 | D26: Из допущений: (Цена − перем.расх.) / Цена
B27: Breakeven (выручка/мес.) | C27: =IFERROR(('💸 Расходы'!O13/12)/(1-'⚙️ Допущения'!C53-(1-'⚙️ Допущения'!C53)*('⚙️ Допущения'!C34+'⚙️ Допущения'!C35+'⚙️ Допущения'!C36)),0) -> 641627.75 | D27: Минимальная выручка для покрытия всех расходов
B28: Breakeven достигнут? | C28: =IF('📊 ОПУ'!N20>0,"✅ Да — в декабре",IF('📊 ОПУ'!O20>0,"✅ Да — в году","❌ Нет в этом году")) -> ✅ Да — в декабре | D28: Вышли ли в прибыль за 12 месяцев
B30: Цвета: синий = ввод в Допущениях | красный = требует внимания | зелёный = хороший показатель
